INFO: 2022-02-19 07:28:06,294: main() 'Using profile folder /home/flandresca/.config/variety/'
INFO: 2022-02-19 07:28:06,301: perform_upgrade() 'Last run version was 0.8.5 or earlier, current version is 0.8.5'
INFO: 2022-02-19 07:28:06,479: process_command() 'Received command: []'
INFO: 2022-02-19 07:28:06,481: load_banned() 'Missing or invalid banned URLs list, no URLs will be banned'
INFO: 2022-02-19 07:28:06,495: start() 'Using data_path /usr/share/variety'
INFO: 2022-02-19 07:28:06,495: load() 'Jumble loading'
INFO: 2022-02-19 07:28:06,495: _walk_modules() 'Jumble loading module in __init__ from /usr/lib/python3.10/site-packages/variety/plugins/builtin/__init__.py'
INFO: 2022-02-19 07:28:06,497: _walk_modules() 'Jumble loading module in WallhavenSource from /usr/lib/python3.10/site-packages/variety/plugins/builtin/downloaders/WallhavenSource.py'
INFO: 2022-02-19 07:28:06,499: load() 'Jumble found plugin class: <class 'WallhavenSource.WallhavenSource'>: {'name': 'WallhavenSource', 'description': 'Configurable source for fetching images from Wallhaven.cc', 'author': 'Peter Levi', 'version': '0.1'}'
INFO: 2022-02-19 07:28:06,500: _walk_modules() 'Jumble loading module in UnsplashConfigurableSource from /usr/lib/python3.10/site-packages/variety/plugins/builtin/downloaders/UnsplashConfigurableSource.py'
INFO: 2022-02-19 07:28:06,501: load() 'Jumble found plugin class: <class 'UnsplashConfigurableSource.UnsplashConfigurableSource'>: {'name': 'UnsplashConfigurableSource', 'description': 'Configurable source for fetching photos from Unsplash.com', 'author': 'Peter Levi', 'version': '0.1'}'
INFO: 2022-02-19 07:28:06,502: _walk_modules() 'Jumble loading module in WallhavenDownloader from /usr/lib/python3.10/site-packages/variety/plugins/builtin/downloaders/WallhavenDownloader.py'
INFO: 2022-02-19 07:28:06,502: _walk_modules() 'Jumble loading module in RedditDownloader from /usr/lib/python3.10/site-packages/variety/plugins/builtin/downloaders/RedditDownloader.py'
INFO: 2022-02-19 07:28:06,503: _walk_modules() 'Jumble loading module in RedditSource from /usr/lib/python3.10/site-packages/variety/plugins/builtin/downloaders/RedditSource.py'
INFO: 2022-02-19 07:28:06,504: load() 'Jumble found plugin class: <class 'RedditSource.RedditSource'>: {'name': 'RedditSource', 'description': 'Configurable source for fetching images from Reddit', 'author': 'Peter Levi', 'version': '0.1'}'
INFO: 2022-02-19 07:28:06,504: _walk_modules() 'Jumble loading module in EarthviewDownloader from /usr/lib/python3.10/site-packages/variety/plugins/builtin/downloaders/EarthviewDownloader.py'
INFO: 2022-02-19 07:28:06,505: load() 'Jumble found plugin class: <class 'EarthviewDownloader.EarthviewDownloader'>: {'name': 'EarthviewDownloader', 'description': 'Google Earth View Wallpapers', 'author': 'Peter Levi', 'version': '0.1'}'
INFO: 2022-02-19 07:28:06,505: _walk_modules() 'Jumble loading module in __init__ from /usr/lib/python3.10/site-packages/variety/plugins/builtin/downloaders/__init__.py'
INFO: 2022-02-19 07:28:06,505: _walk_modules() 'Jumble loading module in UnsplashDownloader from /usr/lib/python3.10/site-packages/variety/plugins/builtin/downloaders/UnsplashDownloader.py'
INFO: 2022-02-19 07:28:06,506: load() 'Jumble found plugin class: <class 'UnsplashDownloader.UnsplashDownloader'>: {'name': 'UnsplashDownloader', 'description': 'High-resolution photos from Unsplash.com', 'author': 'Peter Levi', 'version': '0.1'}'
INFO: 2022-02-19 07:28:06,506: _walk_modules() 'Jumble loading module in MediaRSSDownloader from /usr/lib/python3.10/site-packages/variety/plugins/builtin/downloaders/MediaRSSDownloader.py'
INFO: 2022-02-19 07:28:06,507: _walk_modules() 'Jumble loading module in MediaRSSSource from /usr/lib/python3.10/site-packages/variety/plugins/builtin/downloaders/MediaRSSSource.py'
INFO: 2022-02-19 07:28:06,508: load() 'Jumble found plugin class: <class 'MediaRSSSource.MediaRSSSource'>: {'name': 'MediaRSSSource', 'description': 'Configurable source for fetching images from MediaRSS feeds', 'author': 'Peter Levi', 'version': '0.1'}'
INFO: 2022-02-19 07:28:06,509: _walk_modules() 'Jumble loading module in APODDownloader from /usr/lib/python3.10/site-packages/variety/plugins/builtin/downloaders/APODDownloader.py'
INFO: 2022-02-19 07:28:06,509: load() 'Jumble found plugin class: <class 'APODDownloader.APODDownloader'>: {'name': 'APODDownloader', 'description': 'NASA Astro Pic of the Day', 'author': 'Peter Levi', 'version': '0.1'}'
INFO: 2022-02-19 07:28:06,510: _walk_modules() 'Jumble loading module in BingDownloader from /usr/lib/python3.10/site-packages/variety/plugins/builtin/downloaders/BingDownloader.py'
INFO: 2022-02-19 07:28:06,511: load() 'Jumble found plugin class: <class 'BingDownloader.BingDownloader'>: {'name': 'BingDownloader', 'description': 'Bing Photo of the Day', 'author': 'Peter Levi', 'version': '0.1'}'
INFO: 2022-02-19 07:28:06,511: _walk_modules() 'Jumble loading module in LocalFilesSource from /usr/lib/python3.10/site-packages/variety/plugins/builtin/quotes/LocalFilesSource.py'
INFO: 2022-02-19 07:28:06,512: load() 'Jumble found plugin class: <class 'LocalFilesSource.LocalFilesSource'>: {'name': 'Local text files', 'description': 'Displays quotes, defined in local text files.\nPut your own txt files in: ~/.config/variety/pluginconfig/quotes/.\nThe file format is:\n\nquote -- author\n.\nsecond quote -- another author\n.\netc...\n\nExample: http://rvelthuis.de/zips/quotes.txt', 'author': 'Peter Levi', 'version': '0.1'}'
INFO: 2022-02-19 07:28:06,513: _walk_modules() 'Jumble loading module in GoodreadsSource from /usr/lib/python3.10/site-packages/variety/plugins/builtin/quotes/GoodreadsSource.py'
INFO: 2022-02-19 07:28:06,525: load() 'Jumble found plugin class: <class 'GoodreadsSource.GoodreadsSource'>: {'name': 'Goodreads', 'description': '从 Goodreads.com 获取箴言', 'author': 'Peter Levi', 'version': '0.1'}'
INFO: 2022-02-19 07:28:06,525: _walk_modules() 'Jumble loading module in FortuneSource from /usr/lib/python3.10/site-packages/variety/plugins/builtin/quotes/FortuneSource.py'
INFO: 2022-02-19 07:28:06,526: load() 'Jumble found plugin class: <class 'FortuneSource.FortuneSource'>: {'name': 'UNIX fortune program', 'description': 'Displays quotes using the UNIX fortune program. You may want to install additional fortune packs, e.g. fortunes-bofh-excuses.', 'author': 'Dan Jones', 'version': '0.1'}'
INFO: 2022-02-19 07:28:06,526: _walk_modules() 'Jumble loading module in __init__ from /usr/lib/python3.10/site-packages/variety/plugins/builtin/quotes/__init__.py'
INFO: 2022-02-19 07:28:06,528: _walk_modules() 'Jumble loading module in QuotationsPageSource from /usr/lib/python3.10/site-packages/variety/plugins/builtin/quotes/QuotationsPageSource.py'
INFO: 2022-02-19 07:28:06,529: load() 'Jumble found plugin class: <class 'QuotationsPageSource.QuotationsPageSource'>: {'name': 'TheQuotationsPage.com', 'description': '从 QuotationsPage.com 获取箴言', 'author': 'Peter Levi', 'version': '0.1'}'
INFO: 2022-02-19 07:28:06,529: _walk_modules() 'Jumble loading module in UrbanDictionarySource from /usr/lib/python3.10/site-packages/variety/plugins/builtin/quotes/UrbanDictionarySource.py'
INFO: 2022-02-19 07:28:06,531: load() 'Jumble found plugin class: <class 'UrbanDictionarySource.UrbanDictionarySource'>: {'name': 'Urban Dictionary', 'description': 'Displays definitions from Urban Dictionary', 'author': 'James Miller', 'version': '0.1'}'
INFO: 2022-02-19 07:28:06,536: reload_config() 'Creating new downloader for type flickr, location user:www.flickr.com/photos/peter-levi/;user_id:93647178@N00;'
INFO: 2022-02-19 07:28:06,536: reload_config() 'Creating new downloader for type apod, location NASA's Astronomy Picture of the Day'
INFO: 2022-02-19 07:28:06,536: reload_config() 'Creating new downloader for type bing, location Bing Photo of the Day'
INFO: 2022-02-19 07:28:06,536: reload_config() 'Creating new downloader for type earthview, location Google Earth View Wallpapers'
INFO: 2022-02-19 07:28:06,536: reload_config() 'Creating new downloader for type unsplash, location High-resolution photos from Unsplash.com'
INFO: 2022-02-19 07:28:06,541: log_options() 'Loaded options:'
INFO: 2022-02-19 07:28:06,541: log_options() 'change_enabled = False'
INFO: 2022-02-19 07:28:06,541: log_options() 'change_interval = 300'
INFO: 2022-02-19 07:28:06,541: log_options() 'change_on_start = False'
INFO: 2022-02-19 07:28:06,541: log_options() 'clipboard_enabled = False'
INFO: 2022-02-19 07:28:06,541: log_options() 'clipboard_hosts = ['wallhaven.cc', 'wallpapers.net', 'flickr.com', 'imgur.com', 'deviantart.com', 'interfacelift.com', 'vladstudio.com', 'imageshack.us', 'deviantart.net', 'imageshack.com']'
INFO: 2022-02-19 07:28:06,541: log_options() 'clipboard_use_whitelist = True'
INFO: 2022-02-19 07:28:06,541: log_options() 'clock_date_font = Ubuntu Condensed, 30'
INFO: 2022-02-19 07:28:06,541: log_options() 'clock_enabled = False'
INFO: 2022-02-19 07:28:06,541: log_options() 'clock_filter = -density 100 -font `fc-match -f '%{file[0]}' '%CLOCK_FONT_NAME'` -pointsize %CLOCK_FONT_SIZE -gravity SouthEast -fill '#00000044' -annotate 0x0+[%HOFFSET+58]+[%VOFFSET+108] '%H:%M' -fill white -annotate 0x0+[%HOFFSET+60]+[%VOFFSET+110] '%H:%M' -font `fc-match -f '%{file[0]}' '%DATE_FONT_NAME'` -pointsize %DATE_FONT_SIZE -fill '#00000044' -annotate 0x0+[%HOFFSET+58]+[%VOFFSET+58] '%A, %B %d' -fill white -annotate 0x0+[%HOFFSET+60]+[%VOFFSET+60] '%A, %B %d''
INFO: 2022-02-19 07:28:06,541: log_options() 'clock_font = Ubuntu Condensed, 70'
INFO: 2022-02-19 07:28:06,541: log_options() 'configfile = /home/flandresca/.config/variety/variety.conf'
INFO: 2022-02-19 07:28:06,541: log_options() 'copyto_enabled = False'
INFO: 2022-02-19 07:28:06,541: log_options() 'copyto_folder = Default'
INFO: 2022-02-19 07:28:06,541: log_options() 'desired_color = [160, 160, 160]'
INFO: 2022-02-19 07:28:06,542: log_options() 'desired_color_enabled = False'
INFO: 2022-02-19 07:28:06,542: log_options() 'download_folder = /home/flandresca/.config/variety/Downloaded'
INFO: 2022-02-19 07:28:06,542: log_options() 'download_preference_ratio = 0.9'
INFO: 2022-02-19 07:28:06,542: log_options() 'favorites_folder = /home/flandresca/.config/variety/Favorites'
INFO: 2022-02-19 07:28:06,542: log_options() 'favorites_operations = [['Downloaded', 'Copy'], ['Fetched', 'Move'], ['Others', 'Copy']]'
INFO: 2022-02-19 07:28:06,542: log_options() 'fetched_folder = /home/flandresca/.config/variety/Fetched'
INFO: 2022-02-19 07:28:06,542: log_options() 'filters = [[False, 'Keep original', ''], [False, 'Grayscale', '-type Grayscale'], [False, 'Heavy blur', '-blur 120x40'], [False, 'Soft blur', '-blur 20x7'], [False, 'Oil painting', '-paint 8'], [False, 'Pointilism', '-spread 10 -noise 3'], [False, 'Pixellate', '-scale 3% -scale 3333%']]'
INFO: 2022-02-19 07:28:06,542: log_options() 'icon = Light'
INFO: 2022-02-19 07:28:06,542: log_options() 'lightness_enabled = False'
INFO: 2022-02-19 07:28:06,542: log_options() 'lightness_mode = 0'
INFO: 2022-02-19 07:28:06,542: log_options() 'min_rating = 4'
INFO: 2022-02-19 07:28:06,542: log_options() 'min_rating_enabled = False'
INFO: 2022-02-19 07:28:06,542: log_options() 'min_size = 80'
INFO: 2022-02-19 07:28:06,542: log_options() 'min_size_enabled = False'
INFO: 2022-02-19 07:28:06,542: log_options() 'quota_enabled = True'
INFO: 2022-02-19 07:28:06,542: log_options() 'quota_size = 1000'
INFO: 2022-02-19 07:28:06,542: log_options() 'quotes_authors = '
INFO: 2022-02-19 07:28:06,542: log_options() 'quotes_bg_color = [80, 80, 80]'
INFO: 2022-02-19 07:28:06,542: log_options() 'quotes_bg_opacity = 55'
INFO: 2022-02-19 07:28:06,542: log_options() 'quotes_change_enabled = False'
INFO: 2022-02-19 07:28:06,542: log_options() 'quotes_change_interval = 300'
INFO: 2022-02-19 07:28:06,542: log_options() 'quotes_disabled_sources = ['Urban Dictionary']'
INFO: 2022-02-19 07:28:06,542: log_options() 'quotes_enabled = False'
INFO: 2022-02-19 07:28:06,542: log_options() 'quotes_favorites_file = /home/flandresca/.config/variety/favorite_quotes.txt'
INFO: 2022-02-19 07:28:06,542: log_options() 'quotes_font = Bitstream Charter 30'
INFO: 2022-02-19 07:28:06,542: log_options() 'quotes_hpos = 100'
INFO: 2022-02-19 07:28:06,542: log_options() 'quotes_max_length = 250'
INFO: 2022-02-19 07:28:06,542: log_options() 'quotes_tags = '
INFO: 2022-02-19 07:28:06,542: log_options() 'quotes_text_color = [255, 255, 255]'
INFO: 2022-02-19 07:28:06,542: log_options() 'quotes_text_shadow = False'
INFO: 2022-02-19 07:28:06,542: log_options() 'quotes_vpos = 40'
INFO: 2022-02-19 07:28:06,542: log_options() 'quotes_width = 70'
INFO: 2022-02-19 07:28:06,542: log_options() 'safe_mode = False'
INFO: 2022-02-19 07:28:06,542: log_options() 'slideshow_custom_enabled = False'
INFO: 2022-02-19 07:28:06,542: log_options() 'slideshow_custom_folder = /home/flandresca'
INFO: 2022-02-19 07:28:06,542: log_options() 'slideshow_downloads_enabled = False'
INFO: 2022-02-19 07:28:06,542: log_options() 'slideshow_fade = 0.4'
INFO: 2022-02-19 07:28:06,542: log_options() 'slideshow_favorites_enabled = True'
INFO: 2022-02-19 07:28:06,542: log_options() 'slideshow_mode = Fullscreen'
INFO: 2022-02-19 07:28:06,543: log_options() 'slideshow_monitor = All'
INFO: 2022-02-19 07:28:06,543: log_options() 'slideshow_pan = 0.05'
INFO: 2022-02-19 07:28:06,543: log_options() 'slideshow_seconds = 6.0'
INFO: 2022-02-19 07:28:06,543: log_options() 'slideshow_sort_order = Random'
INFO: 2022-02-19 07:28:06,543: log_options() 'slideshow_sources_enabled = True'
INFO: 2022-02-19 07:28:06,543: log_options() 'slideshow_zoom = 0.2'
INFO: 2022-02-19 07:28:06,543: log_options() 'smart_enabled = False'
INFO: 2022-02-19 07:28:06,543: log_options() 'smart_notice_shown = False'
INFO: 2022-02-19 07:28:06,543: log_options() 'smart_register_shown = False'
INFO: 2022-02-19 07:28:06,543: log_options() 'sources = [[True, 'favorites', 'The Favorites folder'], [True, 'fetched', 'The Fetched folder'], [True, 'folder', '/usr/share/backgrounds'], [True, 'flickr', 'user:www.flickr.com/photos/peter-levi/;user_id:93647178@N00;'], [True, 'apod', "NASA's Astronomy Picture of the Day"], [True, 'bing', 'Bing Photo of the Day'], [True, 'earthview', 'Google Earth View Wallpapers'], [True, 'unsplash', 'High-resolution photos from Unsplash.com']]'
INFO: 2022-02-19 07:28:06,543: log_options() 'stats_enabled = True'
INFO: 2022-02-19 07:28:06,543: log_options() 'stats_notice_shown = False'
INFO: 2022-02-19 07:28:06,543: log_options() 'sync_enabled = True'
INFO: 2022-02-19 07:28:06,543: log_options() 'use_landscape_enabled = True'
INFO: 2022-02-19 07:28:06,543: reload_config() 'No need to clear prepared queue'
INFO: 2022-02-19 07:28:06,543: update_indicator() 'Setting file info to: /usr/share/backgrounds/manjaro-wallpapers-18.0/manjaro-cat.jpg'
INFO: 2022-02-19 07:28:06,550: load_last_change_time() 'Change interval < 6 hours, ignore persisted last_change_time, wait initially the whole interval: 300'
INFO: 2022-02-19 07:28:06,550: update_indicator() 'Setting file info to: /usr/share/backgrounds/manjaro-wallpapers-18.0/manjaro-cat.jpg'
INFO: 2022-02-19 07:28:06,550: regular_change_thread() 'regular_change thread running'
INFO: 2022-02-19 07:28:06,551: regular_change_thread() 'regular_change: waiting till user resumes'
INFO: 2022-02-19 07:28:06,551: prepare_thread() 'Prepare thread running'
INFO: 2022-02-19 07:28:06,551: prepare_thread() 'Prepared buffer contains 0 images'
INFO: 2022-02-19 07:28:06,551: prepare_thread() 'Preparing some images'
INFO: 2022-02-19 07:28:06,551: get_throttling() 'Flickr: parsing serverside options'
INFO: 2022-02-19 07:28:06,552: get_throttling() 'Could not parse Flickr serverside options, using defaults 120, 20'
INFO: 2022-02-19 07:28:06,552: get_throttling() 'Flickr: parsing serverside options'
INFO: 2022-02-19 07:28:06,552: get_throttling() 'Could not parse Flickr serverside options, using defaults 120, 20'
INFO: 2022-02-19 07:28:06,552: download_one() 'Flickr: Downloading an image, config: user:www.flickr.com/photos/peter-levi/;user_id:93647178@N00;'
INFO: 2022-02-19 07:28:06,552: download_one() 'Flickr: Queue size: 0'
INFO: 2022-02-19 07:28:06,552: get_throttling() 'Flickr: parsing serverside options'
INFO: 2022-02-19 07:28:06,552: get_throttling() 'Could not parse Flickr serverside options, using defaults 120, 20'
INFO: 2022-02-19 07:28:06,552: download_one() 'Flickr: Filling queue'
INFO: 2022-02-19 07:28:06,552: fetch() 'Making flickr API call: https://api.flickr.com/services/rest/?method=flickr.photos.search&api_key=0553a848c09bcfd21d3a984d9408c04e&per_page=500&tag_mode=all&format=json&nojsoncallback=1&user_id=93647178@N00'
INFO: 2022-02-19 07:28:06,553: update_indicator_icon() 'Creating indicator'
WARNING: 2022-02-19 07:28:06,575: create_menu() 'Variety Slideshow is not installed. This is an optional extension adding pan-and-zoom slideshows to Variety: see https://github.com/peterlevi/variety-slideshow for details'
INFO: 2022-02-19 07:28:06,576: create_indicator() 'indicator backend: AppIndicator3'
INFO: 2022-02-19 07:28:06,600: set_from_theme_icon() 'Showing indicator icon variety-indicator from GTK theme'
INFO: 2022-02-19 07:28:06,655: do_set_wp() 'Calling do_set_wp with /usr/share/backgrounds/manjaro-wallpapers-18.0/manjaro-cat.jpg, time: 1645226886.6555994'
INFO: 2022-02-19 07:28:06,665: update_indicator() 'Setting file info to: /usr/share/backgrounds/manjaro-wallpapers-18.0/manjaro-cat.jpg'
INFO: 2022-02-19 07:28:06,666: list_files() 'More than 1 files in the folders, stop listing'
ERROR: 2022-02-19 07:28:06,664: image_ok() 'Error in image_ok for file /usr/share/backgrounds/gnome/Blobs.svg'
Traceback (most recent call last):
  File "/usr/lib/python3.10/site-packages/variety/VarietyWindow.py", line 1761, in image_ok
    i = PILImage.open(img)
  File "/usr/lib/python3.10/site-packages/PIL/Image.py", line 3008, in open
    raise UnidentifiedImageError(
PIL.UnidentifiedImageError: cannot identify image file '/usr/share/backgrounds/gnome/Blobs.svg'
INFO: 2022-02-19 07:28:06,725: prepare_thread() 'After search prepared buffer contains 98 images'
INFO: 2022-02-19 07:28:08,216: reload() 'Reloading preferences dialog'
INFO: 2022-02-19 07:28:08,726: trigger_download() 'Triggering download thread to check if download needed'
ERROR: 2022-02-19 07:28:11,591: download_one_from() 'Could not download wallpaper:'
Traceback (most recent call last):
  File "/usr/lib/python3.10/site-packages/urllib3/connection.py", line 174, in _new_conn
    conn = connection.create_connection(
  File "/usr/lib/python3.10/site-packages/urllib3/util/connection.py", line 96, in create_connection
    raise err
  File "/usr/lib/python3.10/site-packages/urllib3/util/connection.py", line 86, in create_connection
    sock.connect(sa)
OSError: [Errno 101] 网络不可达

During handling of the above exception, another exception occurred:

Traceback (most recent call last):
  File "/usr/lib/python3.10/site-packages/urllib3/connectionpool.py", line 699, in urlopen
    httplib_response = self._make_request(
  File "/usr/lib/python3.10/site-packages/urllib3/connectionpool.py", line 382, in _make_request
    self._validate_conn(conn)
  File "/usr/lib/python3.10/site-packages/urllib3/connectionpool.py", line 1010, in _validate_conn
    conn.connect()
  File "/usr/lib/python3.10/site-packages/urllib3/connection.py", line 358, in connect
    conn = self._new_conn()
  File "/usr/lib/python3.10/site-packages/urllib3/connection.py", line 186, in _new_conn
    raise NewConnectionError(
urllib3.exceptions.NewConnectionError: <urllib3.connection.HTTPSConnection object at 0x7f170e8419f0>: Failed to establish a new connection: [Errno 101] 网络不可达

During handling of the above exception, another exception occurred:

Traceback (most recent call last):
  File "/usr/lib/python3.10/site-packages/requests/adapters.py", line 439, in send
    resp = conn.urlopen(
  File "/usr/lib/python3.10/site-packages/urllib3/connectionpool.py", line 755, in urlopen
    retries = retries.increment(
  File "/usr/lib/python3.10/site-packages/urllib3/util/retry.py", line 574, in increment
    raise MaxRetryError(_pool, url, error or ResponseError(cause))
urllib3.exceptions.MaxRetryError: HTTPSConnectionPool(host='api.flickr.com', port=443): Max retries exceeded with url: /services/rest/?method=flickr.photos.search&api_key=0553a848c09bcfd21d3a984d9408c04e&per_page=500&tag_mode=all&format=json&nojsoncallback=1&user_id=93647178@N00 (Caused by NewConnectionError('<urllib3.connection.HTTPSConnection object at 0x7f170e8419f0>: Failed to establish a new connection: [Errno 101] 网络不可达'))

During handling of the above exception, another exception occurred:

Traceback (most recent call last):
  File "/usr/lib/python3.10/site-packages/variety/VarietyWindow.py", line 1160, in download_one_from
    file = downloader.download_one()
  File "/usr/lib/python3.10/site-packages/variety/plugins/downloaders/DefaultDownloader.py", line 141, in download_one
    items = self.fill_queue()
  File "/usr/lib/python3.10/site-packages/variety/FlickrDownloader.py", line 161, in fill_queue
    resp = FlickrDownloader.fetch(call)
  File "/usr/lib/python3.10/site-packages/variety/FlickrDownloader.py", line 74, in fetch
    return Util.fetch_json(call)
  File "/usr/lib/python3.10/site-packages/variety/Util.py", line 644, in fetch_json
    return Util.request(url, data, **request_kwargs).json()
  File "/usr/lib/python3.10/site-packages/variety/Util.py", line 614, in request
    r = requests.request(
  File "/usr/lib/python3.10/site-packages/requests/api.py", line 61, in request
    return session.request(method=method, url=url, **kwargs)
  File "/usr/lib/python3.10/site-packages/requests/sessions.py", line 542, in request
    resp = self.send(prep, **send_kwargs)
  File "/usr/lib/python3.10/site-packages/requests/sessions.py", line 655, in send
    r = adapter.send(request, **kwargs)
  File "/usr/lib/python3.10/site-packages/requests/adapters.py", line 516, in send
    raise ConnectionError(e, request=request)
requests.exceptions.ConnectionError: HTTPSConnectionPool(host='api.flickr.com', port=443): Max retries exceeded with url: /services/rest/?method=flickr.photos.search&api_key=0553a848c09bcfd21d3a984d9408c04e&per_page=500&tag_mode=all&format=json&nojsoncallback=1&user_id=93647178@N00 (Caused by NewConnectionError('<urllib3.connection.HTTPSConnection object at 0x7f170e8419f0>: Failed to establish a new connection: [Errno 101] 网络不可达'))
INFO: 2022-02-19 07:28:26,571: server_options_thread() 'Fetching server options from http://tiny.cc/variety-options-063'
ERROR: 2022-02-19 07:28:31,613: server_options_thread() 'Could not fetch Variety serverside options'
Traceback (most recent call last):
  File "/usr/lib/python3.10/site-packages/urllib3/connection.py", line 174, in _new_conn
    conn = connection.create_connection(
  File "/usr/lib/python3.10/site-packages/urllib3/util/connection.py", line 96, in create_connection
    raise err
  File "/usr/lib/python3.10/site-packages/urllib3/util/connection.py", line 86, in create_connection
    sock.connect(sa)
OSError: [Errno 101] 网络不可达

During handling of the above exception, another exception occurred:

Traceback (most recent call last):
  File "/usr/lib/python3.10/site-packages/urllib3/connectionpool.py", line 699, in urlopen
    httplib_response = self._make_request(
  File "/usr/lib/python3.10/site-packages/urllib3/connectionpool.py", line 394, in _make_request
    conn.request(method, url, **httplib_request_kw)
  File "/usr/lib/python3.10/site-packages/urllib3/connection.py", line 239, in request
    super(HTTPConnection, self).request(method, url, body=body, headers=headers)
  File "/usr/lib/python3.10/http/client.py", line 1282, in request
    self._send_request(method, url, body, headers, encode_chunked)
  File "/usr/lib/python3.10/http/client.py", line 1328, in _send_request
    self.endheaders(body, encode_chunked=encode_chunked)
  File "/usr/lib/python3.10/http/client.py", line 1277, in endheaders
    self._send_output(message_body, encode_chunked=encode_chunked)
  File "/usr/lib/python3.10/http/client.py", line 1037, in _send_output
    self.send(msg)
  File "/usr/lib/python3.10/http/client.py", line 975, in send
    self.connect()
  File "/usr/lib/python3.10/site-packages/urllib3/connection.py", line 205, in connect
    conn = self._new_conn()
  File "/usr/lib/python3.10/site-packages/urllib3/connection.py", line 186, in _new_conn
    raise NewConnectionError(
urllib3.exceptions.NewConnectionError: <urllib3.connection.HTTPConnection object at 0x7f16f4680190>: Failed to establish a new connection: [Errno 101] 网络不可达

During handling of the above exception, another exception occurred:

Traceback (most recent call last):
  File "/usr/lib/python3.10/site-packages/requests/adapters.py", line 439, in send
    resp = conn.urlopen(
  File "/usr/lib/python3.10/site-packages/urllib3/connectionpool.py", line 755, in urlopen
    retries = retries.increment(
  File "/usr/lib/python3.10/site-packages/urllib3/util/retry.py", line 574, in increment
    raise MaxRetryError(_pool, url, error or ResponseError(cause))
urllib3.exceptions.MaxRetryError: HTTPConnectionPool(host='tiny.cc', port=80): Max retries exceeded with url: /variety-options-063 (Caused by NewConnectionError('<urllib3.connection.HTTPConnection object at 0x7f16f4680190>: Failed to establish a new connection: [Errno 101] 网络不可达'))

During handling of the above exception, another exception occurred:

Traceback (most recent call last):
  File "/usr/lib/python3.10/site-packages/variety/VarietyWindow.py", line 1086, in server_options_thread
    self.server_options = Util.fetch_json(VarietyWindow.SERVERSIDE_OPTIONS_URL)
  File "/usr/lib/python3.10/site-packages/variety/Util.py", line 644, in fetch_json
    return Util.request(url, data, **request_kwargs).json()
  File "/usr/lib/python3.10/site-packages/variety/Util.py", line 614, in request
    r = requests.request(
  File "/usr/lib/python3.10/site-packages/requests/api.py", line 61, in request
    return session.request(method=method, url=url, **kwargs)
  File "/usr/lib/python3.10/site-packages/requests/sessions.py", line 542, in request
    resp = self.send(prep, **send_kwargs)
  File "/usr/lib/python3.10/site-packages/requests/sessions.py", line 655, in send
    r = adapter.send(request, **kwargs)
  File "/usr/lib/python3.10/site-packages/requests/adapters.py", line 516, in send
    raise ConnectionError(e, request=request)
requests.exceptions.ConnectionError: HTTPConnectionPool(host='tiny.cc', port=80): Max retries exceeded with url: /variety-options-063 (Caused by NewConnectionError('<urllib3.connection.HTTPConnection object at 0x7f16f4680190>: Failed to establish a new connection: [Errno 101] 网络不可达'))
INFO: 2022-02-19 07:29:01,645: server_options_thread() 'Fetching server options from http://tiny.cc/variety-options-063'
ERROR: 2022-02-19 07:29:11,781: server_options_thread() 'Could not fetch Variety serverside options'
Traceback (most recent call last):
  File "/usr/lib/python3.10/site-packages/urllib3/connection.py", line 174, in _new_conn
    conn = connection.create_connection(
  File "/usr/lib/python3.10/site-packages/urllib3/util/connection.py", line 96, in create_connection
    raise err
  File "/usr/lib/python3.10/site-packages/urllib3/util/connection.py", line 86, in create_connection
    sock.connect(sa)
OSError: [Errno 101] 网络不可达

During handling of the above exception, another exception occurred:

Traceback (most recent call last):
  File "/usr/lib/python3.10/site-packages/urllib3/connectionpool.py", line 699, in urlopen
    httplib_response = self._make_request(
  File "/usr/lib/python3.10/site-packages/urllib3/connectionpool.py", line 394, in _make_request
    conn.request(method, url, **httplib_request_kw)
  File "/usr/lib/python3.10/site-packages/urllib3/connection.py", line 239, in request
    super(HTTPConnection, self).request(method, url, body=body, headers=headers)
  File "/usr/lib/python3.10/http/client.py", line 1282, in request
    self._send_request(method, url, body, headers, encode_chunked)
  File "/usr/lib/python3.10/http/client.py", line 1328, in _send_request
    self.endheaders(body, encode_chunked=encode_chunked)
  File "/usr/lib/python3.10/http/client.py", line 1277, in endheaders
    self._send_output(message_body, encode_chunked=encode_chunked)
  File "/usr/lib/python3.10/http/client.py", line 1037, in _send_output
    self.send(msg)
  File "/usr/lib/python3.10/http/client.py", line 975, in send
    self.connect()
  File "/usr/lib/python3.10/site-packages/urllib3/connection.py", line 205, in connect
    conn = self._new_conn()
  File "/usr/lib/python3.10/site-packages/urllib3/connection.py", line 186, in _new_conn
    raise NewConnectionError(
urllib3.exceptions.NewConnectionError: <urllib3.connection.HTTPConnection object at 0x7f16f4680880>: Failed to establish a new connection: [Errno 101] 网络不可达

During handling of the above exception, another exception occurred:

Traceback (most recent call last):
  File "/usr/lib/python3.10/site-packages/requests/adapters.py", line 439, in send
    resp = conn.urlopen(
  File "/usr/lib/python3.10/site-packages/urllib3/connectionpool.py", line 755, in urlopen
    retries = retries.increment(
  File "/usr/lib/python3.10/site-packages/urllib3/util/retry.py", line 574, in increment
    raise MaxRetryError(_pool, url, error or ResponseError(cause))
urllib3.exceptions.MaxRetryError: HTTPConnectionPool(host='tiny.cc', port=80): Max retries exceeded with url: /variety-options-063 (Caused by NewConnectionError('<urllib3.connection.HTTPConnection object at 0x7f16f4680880>: Failed to establish a new connection: [Errno 101] 网络不可达'))

During handling of the above exception, another exception occurred:

Traceback (most recent call last):
  File "/usr/lib/python3.10/site-packages/variety/VarietyWindow.py", line 1086, in server_options_thread
    self.server_options = Util.fetch_json(VarietyWindow.SERVERSIDE_OPTIONS_URL)
  File "/usr/lib/python3.10/site-packages/variety/Util.py", line 644, in fetch_json
    return Util.request(url, data, **request_kwargs).json()
  File "/usr/lib/python3.10/site-packages/variety/Util.py", line 614, in request
    r = requests.request(
  File "/usr/lib/python3.10/site-packages/requests/api.py", line 61, in request
    return session.request(method=method, url=url, **kwargs)
  File "/usr/lib/python3.10/site-packages/requests/sessions.py", line 542, in request
    resp = self.send(prep, **send_kwargs)
  File "/usr/lib/python3.10/site-packages/requests/sessions.py", line 655, in send
    r = adapter.send(request, **kwargs)
  File "/usr/lib/python3.10/site-packages/requests/adapters.py", line 516, in send
    raise ConnectionError(e, request=request)
requests.exceptions.ConnectionError: HTTPConnectionPool(host='tiny.cc', port=80): Max retries exceeded with url: /variety-options-063 (Caused by NewConnectionError('<urllib3.connection.HTTPConnection object at 0x7f16f4680880>: Failed to establish a new connection: [Errno 101] 网络不可达'))
INFO: 2022-02-19 07:29:41,812: server_options_thread() 'Fetching server options from http://tiny.cc/variety-options-063'
ERROR: 2022-02-19 07:29:46,846: server_options_thread() 'Could not fetch Variety serverside options'
Traceback (most recent call last):
  File "/usr/lib/python3.10/site-packages/urllib3/connection.py", line 174, in _new_conn
    conn = connection.create_connection(
  File "/usr/lib/python3.10/site-packages/urllib3/util/connection.py", line 96, in create_connection
    raise err
  File "/usr/lib/python3.10/site-packages/urllib3/util/connection.py", line 86, in create_connection
    sock.connect(sa)
OSError: [Errno 101] 网络不可达

During handling of the above exception, another exception occurred:

Traceback (most recent call last):
  File "/usr/lib/python3.10/site-packages/urllib3/connectionpool.py", line 699, in urlopen
    httplib_response = self._make_request(
  File "/usr/lib/python3.10/site-packages/urllib3/connectionpool.py", line 394, in _make_request
    conn.request(method, url, **httplib_request_kw)
  File "/usr/lib/python3.10/site-packages/urllib3/connection.py", line 239, in request
    super(HTTPConnection, self).request(method, url, body=body, headers=headers)
  File "/usr/lib/python3.10/http/client.py", line 1282, in request
    self._send_request(method, url, body, headers, encode_chunked)
  File "/usr/lib/python3.10/http/client.py", line 1328, in _send_request
    self.endheaders(body, encode_chunked=encode_chunked)
  File "/usr/lib/python3.10/http/client.py", line 1277, in endheaders
    self._send_output(message_body, encode_chunked=encode_chunked)
  File "/usr/lib/python3.10/http/client.py", line 1037, in _send_output
    self.send(msg)
  File "/usr/lib/python3.10/http/client.py", line 975, in send
    self.connect()
  File "/usr/lib/python3.10/site-packages/urllib3/connection.py", line 205, in connect
    conn = self._new_conn()
  File "/usr/lib/python3.10/site-packages/urllib3/connection.py", line 186, in _new_conn
    raise NewConnectionError(
urllib3.exceptions.NewConnectionError: <urllib3.connection.HTTPConnection object at 0x7f16f4680fd0>: Failed to establish a new connection: [Errno 101] 网络不可达

During handling of the above exception, another exception occurred:

Traceback (most recent call last):
  File "/usr/lib/python3.10/site-packages/requests/adapters.py", line 439, in send
    resp = conn.urlopen(
  File "/usr/lib/python3.10/site-packages/urllib3/connectionpool.py", line 755, in urlopen
    retries = retries.increment(
  File "/usr/lib/python3.10/site-packages/urllib3/util/retry.py", line 574, in increment
    raise MaxRetryError(_pool, url, error or ResponseError(cause))
urllib3.exceptions.MaxRetryError: HTTPConnectionPool(host='tiny.cc', port=80): Max retries exceeded with url: /variety-options-063 (Caused by NewConnectionError('<urllib3.connection.HTTPConnection object at 0x7f16f4680fd0>: Failed to establish a new connection: [Errno 101] 网络不可达'))

During handling of the above exception, another exception occurred:

Traceback (most recent call last):
  File "/usr/lib/python3.10/site-packages/variety/VarietyWindow.py", line 1086, in server_options_thread
    self.server_options = Util.fetch_json(VarietyWindow.SERVERSIDE_OPTIONS_URL)
  File "/usr/lib/python3.10/site-packages/variety/Util.py", line 644, in fetch_json
    return Util.request(url, data, **request_kwargs).json()
  File "/usr/lib/python3.10/site-packages/variety/Util.py", line 614, in request
    r = requests.request(
  File "/usr/lib/python3.10/site-packages/requests/api.py", line 61, in request
    return session.request(method=method, url=url, **kwargs)
  File "/usr/lib/python3.10/site-packages/requests/sessions.py", line 542, in request
    resp = self.send(prep, **send_kwargs)
  File "/usr/lib/python3.10/site-packages/requests/sessions.py", line 655, in send
    r = adapter.send(request, **kwargs)
  File "/usr/lib/python3.10/site-packages/requests/adapters.py", line 516, in send
    raise ConnectionError(e, request=request)
requests.exceptions.ConnectionError: HTTPConnectionPool(host='tiny.cc', port=80): Max retries exceeded with url: /variety-options-063 (Caused by NewConnectionError('<urllib3.connection.HTTPConnection object at 0x7f16f4680fd0>: Failed to establish a new connection: [Errno 101] 网络不可达'))
INFO: 2022-02-19 07:30:16,875: server_options_thread() 'Fetching server options from http://tiny.cc/variety-options-063'
ERROR: 2022-02-19 07:30:21,896: server_options_thread() 'Could not fetch Variety serverside options'
Traceback (most recent call last):
  File "/usr/lib/python3.10/site-packages/urllib3/connection.py", line 174, in _new_conn
    conn = connection.create_connection(
  File "/usr/lib/python3.10/site-packages/urllib3/util/connection.py", line 96, in create_connection
    raise err
  File "/usr/lib/python3.10/site-packages/urllib3/util/connection.py", line 86, in create_connection
    sock.connect(sa)
OSError: [Errno 101] 网络不可达

During handling of the above exception, another exception occurred:

Traceback (most recent call last):
  File "/usr/lib/python3.10/site-packages/urllib3/connectionpool.py", line 699, in urlopen
    httplib_response = self._make_request(
  File "/usr/lib/python3.10/site-packages/urllib3/connectionpool.py", line 394, in _make_request
    conn.request(method, url, **httplib_request_kw)
  File "/usr/lib/python3.10/site-packages/urllib3/connection.py", line 239, in request
    super(HTTPConnection, self).request(method, url, body=body, headers=headers)
  File "/usr/lib/python3.10/http/client.py", line 1282, in request
    self._send_request(method, url, body, headers, encode_chunked)
  File "/usr/lib/python3.10/http/client.py", line 1328, in _send_request
    self.endheaders(body, encode_chunked=encode_chunked)
  File "/usr/lib/python3.10/http/client.py", line 1277, in endheaders
    self._send_output(message_body, encode_chunked=encode_chunked)
  File "/usr/lib/python3.10/http/client.py", line 1037, in _send_output
    self.send(msg)
  File "/usr/lib/python3.10/http/client.py", line 975, in send
    self.connect()
  File "/usr/lib/python3.10/site-packages/urllib3/connection.py", line 205, in connect
    conn = self._new_conn()
  File "/usr/lib/python3.10/site-packages/urllib3/connection.py", line 186, in _new_conn
    raise NewConnectionError(
urllib3.exceptions.NewConnectionError: <urllib3.connection.HTTPConnection object at 0x7f16f4681720>: Failed to establish a new connection: [Errno 101] 网络不可达

During handling of the above exception, another exception occurred:

Traceback (most recent call last):
  File "/usr/lib/python3.10/site-packages/requests/adapters.py", line 439, in send
    resp = conn.urlopen(
  File "/usr/lib/python3.10/site-packages/urllib3/connectionpool.py", line 755, in urlopen
    retries = retries.increment(
  File "/usr/lib/python3.10/site-packages/urllib3/util/retry.py", line 574, in increment
    raise MaxRetryError(_pool, url, error or ResponseError(cause))
urllib3.exceptions.MaxRetryError: HTTPConnectionPool(host='tiny.cc', port=80): Max retries exceeded with url: /variety-options-063 (Caused by NewConnectionError('<urllib3.connection.HTTPConnection object at 0x7f16f4681720>: Failed to establish a new connection: [Errno 101] 网络不可达'))

During handling of the above exception, another exception occurred:

Traceback (most recent call last):
  File "/usr/lib/python3.10/site-packages/variety/VarietyWindow.py", line 1086, in server_options_thread
    self.server_options = Util.fetch_json(VarietyWindow.SERVERSIDE_OPTIONS_URL)
  File "/usr/lib/python3.10/site-packages/variety/Util.py", line 644, in fetch_json
    return Util.request(url, data, **request_kwargs).json()
  File "/usr/lib/python3.10/site-packages/variety/Util.py", line 614, in request
    r = requests.request(
  File "/usr/lib/python3.10/site-packages/requests/api.py", line 61, in request
    return session.request(method=method, url=url, **kwargs)
  File "/usr/lib/python3.10/site-packages/requests/sessions.py", line 542, in request
    resp = self.send(prep, **send_kwargs)
  File "/usr/lib/python3.10/site-packages/requests/sessions.py", line 655, in send
    r = adapter.send(request, **kwargs)
  File "/usr/lib/python3.10/site-packages/requests/adapters.py", line 516, in send
    raise ConnectionError(e, request=request)
requests.exceptions.ConnectionError: HTTPConnectionPool(host='tiny.cc', port=80): Max retries exceeded with url: /variety-options-063 (Caused by NewConnectionError('<urllib3.connection.HTTPConnection object at 0x7f16f4681720>: Failed to establish a new connection: [Errno 101] 网络不可达'))
INFO: 2022-02-19 07:30:51,928: server_options_thread() 'Fetching server options from http://tiny.cc/variety-options-063'
ERROR: 2022-02-19 07:30:56,960: server_options_thread() 'Could not fetch Variety serverside options'
Traceback (most recent call last):
  File "/usr/lib/python3.10/site-packages/urllib3/connection.py", line 174, in _new_conn
    conn = connection.create_connection(
  File "/usr/lib/python3.10/site-packages/urllib3/util/connection.py", line 96, in create_connection
    raise err
  File "/usr/lib/python3.10/site-packages/urllib3/util/connection.py", line 86, in create_connection
    sock.connect(sa)
OSError: [Errno 101] 网络不可达

During handling of the above exception, another exception occurred:

Traceback (most recent call last):
  File "/usr/lib/python3.10/site-packages/urllib3/connectionpool.py", line 699, in urlopen
    httplib_response = self._make_request(
  File "/usr/lib/python3.10/site-packages/urllib3/connectionpool.py", line 394, in _make_request
    conn.request(method, url, **httplib_request_kw)
  File "/usr/lib/python3.10/site-packages/urllib3/connection.py", line 239, in request
    super(HTTPConnection, self).request(method, url, body=body, headers=headers)
  File "/usr/lib/python3.10/http/client.py", line 1282, in request
    self._send_request(method, url, body, headers, encode_chunked)
  File "/usr/lib/python3.10/http/client.py", line 1328, in _send_request
    self.endheaders(body, encode_chunked=encode_chunked)
  File "/usr/lib/python3.10/http/client.py", line 1277, in endheaders
    self._send_output(message_body, encode_chunked=encode_chunked)
  File "/usr/lib/python3.10/http/client.py", line 1037, in _send_output
    self.send(msg)
  File "/usr/lib/python3.10/http/client.py", line 975, in send
    self.connect()
  File "/usr/lib/python3.10/site-packages/urllib3/connection.py", line 205, in connect
    conn = self._new_conn()
  File "/usr/lib/python3.10/site-packages/urllib3/connection.py", line 186, in _new_conn
    raise NewConnectionError(
urllib3.exceptions.NewConnectionError: <urllib3.connection.HTTPConnection object at 0x7f16f4681e70>: Failed to establish a new connection: [Errno 101] 网络不可达

During handling of the above exception, another exception occurred:

Traceback (most recent call last):
  File "/usr/lib/python3.10/site-packages/requests/adapters.py", line 439, in send
    resp = conn.urlopen(
  File "/usr/lib/python3.10/site-packages/urllib3/connectionpool.py", line 755, in urlopen
    retries = retries.increment(
  File "/usr/lib/python3.10/site-packages/urllib3/util/retry.py", line 574, in increment
    raise MaxRetryError(_pool, url, error or ResponseError(cause))
urllib3.exceptions.MaxRetryError: HTTPConnectionPool(host='tiny.cc', port=80): Max retries exceeded with url: /variety-options-063 (Caused by NewConnectionError('<urllib3.connection.HTTPConnection object at 0x7f16f4681e70>: Failed to establish a new connection: [Errno 101] 网络不可达'))

During handling of the above exception, another exception occurred:

Traceback (most recent call last):
  File "/usr/lib/python3.10/site-packages/variety/VarietyWindow.py", line 1086, in server_options_thread
    self.server_options = Util.fetch_json(VarietyWindow.SERVERSIDE_OPTIONS_URL)
  File "/usr/lib/python3.10/site-packages/variety/Util.py", line 644, in fetch_json
    return Util.request(url, data, **request_kwargs).json()
  File "/usr/lib/python3.10/site-packages/variety/Util.py", line 614, in request
    r = requests.request(
  File "/usr/lib/python3.10/site-packages/requests/api.py", line 61, in request
    return session.request(method=method, url=url, **kwargs)
  File "/usr/lib/python3.10/site-packages/requests/sessions.py", line 542, in request
    resp = self.send(prep, **send_kwargs)
  File "/usr/lib/python3.10/site-packages/requests/sessions.py", line 655, in send
    r = adapter.send(request, **kwargs)
  File "/usr/lib/python3.10/site-packages/requests/adapters.py", line 516, in send
    raise ConnectionError(e, request=request)
requests.exceptions.ConnectionError: HTTPConnectionPool(host='tiny.cc', port=80): Max retries exceeded with url: /variety-options-063 (Caused by NewConnectionError('<urllib3.connection.HTTPConnection object at 0x7f16f4681e70>: Failed to establish a new connection: [Errno 101] 网络不可达'))
INFO: 2022-02-19 07:31:12,599: get_throttling() 'Flickr: parsing serverside options'
INFO: 2022-02-19 07:31:12,599: get_throttling() 'Could not parse Flickr serverside options, using defaults 120, 20'
INFO: 2022-02-19 07:31:12,600: get_throttling() 'Flickr: parsing serverside options'
INFO: 2022-02-19 07:31:12,600: get_throttling() 'Could not parse Flickr serverside options, using defaults 120, 20'
INFO: 2022-02-19 07:31:12,600: download_one() 'Flickr: Downloading an image, config: user:www.flickr.com/photos/peter-levi/;user_id:93647178@N00;'
INFO: 2022-02-19 07:31:12,600: download_one() 'Flickr: Queue size: 0'
INFO: 2022-02-19 07:31:12,600: get_throttling() 'Flickr: parsing serverside options'
INFO: 2022-02-19 07:31:12,601: get_throttling() 'Could not parse Flickr serverside options, using defaults 120, 20'
INFO: 2022-02-19 07:31:12,601: download_one() 'Flickr: Filling queue'
INFO: 2022-02-19 07:31:12,601: fetch() 'Making flickr API call: https://api.flickr.com/services/rest/?method=flickr.photos.search&api_key=0553a848c09bcfd21d3a984d9408c04e&per_page=500&tag_mode=all&format=json&nojsoncallback=1&user_id=93647178@N00'
ERROR: 2022-02-19 07:31:17,628: download_one_from() 'Could not download wallpaper:'
Traceback (most recent call last):
  File "/usr/lib/python3.10/site-packages/urllib3/connection.py", line 174, in _new_conn
    conn = connection.create_connection(
  File "/usr/lib/python3.10/site-packages/urllib3/util/connection.py", line 96, in create_connection
    raise err
  File "/usr/lib/python3.10/site-packages/urllib3/util/connection.py", line 86, in create_connection
    sock.connect(sa)
OSError: [Errno 101] 网络不可达

During handling of the above exception, another exception occurred:

Traceback (most recent call last):
  File "/usr/lib/python3.10/site-packages/urllib3/connectionpool.py", line 699, in urlopen
    httplib_response = self._make_request(
  File "/usr/lib/python3.10/site-packages/urllib3/connectionpool.py", line 382, in _make_request
    self._validate_conn(conn)
  File "/usr/lib/python3.10/site-packages/urllib3/connectionpool.py", line 1010, in _validate_conn
    conn.connect()
  File "/usr/lib/python3.10/site-packages/urllib3/connection.py", line 358, in connect
    conn = self._new_conn()
  File "/usr/lib/python3.10/site-packages/urllib3/connection.py", line 186, in _new_conn
    raise NewConnectionError(
urllib3.exceptions.NewConnectionError: <urllib3.connection.HTTPSConnection object at 0x7f170c253280>: Failed to establish a new connection: [Errno 101] 网络不可达

During handling of the above exception, another exception occurred:

Traceback (most recent call last):
  File "/usr/lib/python3.10/site-packages/requests/adapters.py", line 439, in send
    resp = conn.urlopen(
  File "/usr/lib/python3.10/site-packages/urllib3/connectionpool.py", line 755, in urlopen
    retries = retries.increment(
  File "/usr/lib/python3.10/site-packages/urllib3/util/retry.py", line 574, in increment
    raise MaxRetryError(_pool, url, error or ResponseError(cause))
urllib3.exceptions.MaxRetryError: HTTPSConnectionPool(host='api.flickr.com', port=443): Max retries exceeded with url: /services/rest/?method=flickr.photos.search&api_key=0553a848c09bcfd21d3a984d9408c04e&per_page=500&tag_mode=all&format=json&nojsoncallback=1&user_id=93647178@N00 (Caused by NewConnectionError('<urllib3.connection.HTTPSConnection object at 0x7f170c253280>: Failed to establish a new connection: [Errno 101] 网络不可达'))

During handling of the above exception, another exception occurred:

Traceback (most recent call last):
  File "/usr/lib/python3.10/site-packages/variety/VarietyWindow.py", line 1160, in download_one_from
    file = downloader.download_one()
  File "/usr/lib/python3.10/site-packages/variety/plugins/downloaders/DefaultDownloader.py", line 141, in download_one
    items = self.fill_queue()
  File "/usr/lib/python3.10/site-packages/variety/FlickrDownloader.py", line 161, in fill_queue
    resp = FlickrDownloader.fetch(call)
  File "/usr/lib/python3.10/site-packages/variety/FlickrDownloader.py", line 74, in fetch
    return Util.fetch_json(call)
  File "/usr/lib/python3.10/site-packages/variety/Util.py", line 644, in fetch_json
    return Util.request(url, data, **request_kwargs).json()
  File "/usr/lib/python3.10/site-packages/variety/Util.py", line 614, in request
    r = requests.request(
  File "/usr/lib/python3.10/site-packages/requests/api.py", line 61, in request
    return session.request(method=method, url=url, **kwargs)
  File "/usr/lib/python3.10/site-packages/requests/sessions.py", line 542, in request
    resp = self.send(prep, **send_kwargs)
  File "/usr/lib/python3.10/site-packages/requests/sessions.py", line 655, in send
    r = adapter.send(request, **kwargs)
  File "/usr/lib/python3.10/site-packages/requests/adapters.py", line 516, in send
    raise ConnectionError(e, request=request)
requests.exceptions.ConnectionError: HTTPSConnectionPool(host='api.flickr.com', port=443): Max retries exceeded with url: /services/rest/?method=flickr.photos.search&api_key=0553a848c09bcfd21d3a984d9408c04e&per_page=500&tag_mode=all&format=json&nojsoncallback=1&user_id=93647178@N00 (Caused by NewConnectionError('<urllib3.connection.HTTPSConnection object at 0x7f170c253280>: Failed to establish a new connection: [Errno 101] 网络不可达'))
